Workbook
Name ACHtest: OFFSET('[1]Cal for MaxMin'!$N$10,,,(COUNTA('[1]Cal for MaxMin'!$N:$N)-1))
Name allach: OFFSET('[1]Cal For TopBottom'!$Z$15,,,(COUNTA('[1]Cal For TopBottom'!$S:$S)-2))
Name allnames: OFFSET('[1]Cal For TopBottom'!$Y$15,,,(COUNTA('[1]Cal For TopBottom'!$R:$R)-2))
Name Category: [2]Sheet3!$I$5:$I$21
Name GoToProductDB: #REF!
Name Gov: [2]Sheet3!$H$5:$H$21
Name Home: #REF!
Name master: IF('[1]Cal For TopBottom'!$Z$12=1,allach,IF('[1]Cal For TopBottom'!$Z$12=2,topch,topch))
Name master: IF('[1]Cal For TopBottom'!$Z$12=1,allach,IF('[1]Cal For TopBottom'!$Z$12=2,topch,topch))
Name Maxtest: OFFSET('[1]Cal for MaxMin'!$R$10,,,(COUNTA('[1]Cal for MaxMin'!$M:$M)-1))
Name Mintest: OFFSET('[1]Cal for MaxMin'!$S$10,,,(COUNTA('[1]Cal for MaxMin'!$M:$M)-1))
Name Months: [2]Sheet3!$F$5:$F$21
Name nametest: OFFSET('[1]Cal for MaxMin'!$M$10,,,(COUNTA('[1]Cal for MaxMin'!$M:$M)-1))
Name OFFSETACH: OFFSET('[1]Cal for MaxMin (2)'!$C$9,,,COUNTA(('[1]Cal for MaxMin (2)'!$C:$C))-2)
Name OFFSETMAX: OFFSET('[1]Cal for MaxMin (2)'!$D$9,,,COUNTA(('[1]Cal for MaxMin (2)'!$B:$B))-2)
Name OFFSETMIN: OFFSET('[1]Cal for MaxMin (2)'!$E$9,,,COUNTA(('[1]Cal for MaxMin (2)'!$B:$B))-2)
Name OFFSETNAMES: OFFSET('[1]Cal for MaxMin (2)'!$B$9,,,COUNTA(('[1]Cal for MaxMin (2)'!$B:$B))-2)
Name Product: [2]Sheet3!$J$5:$J$21
Name ProductLogo: INDIRECT([3]Products!$B$14)
Name Region: [2]Sheet3!$G$5:$G$21
Name silver: الفضه!$A$2:$C$253
Name Slicer_السنه: #N/A
Name SMLink: #REF!
Name SMLINKK: #REF!
Name topch: OFFSET('[1]Cal For TopBottom'!$Z$15,,,3)

Sheet اكبر شركات فى البورضة 
A1: Date | B1: السنه | C1: Price | D1: Open | E1: High | F1: Low | G1: Vol. | H1: Change %
A2: 45992 | B2: 2025 | C2: 41828.97 | D2: 40753.45 | E2: 42624.11 | F2: 40515.15 | G2: 10.39B | H2: 0.0264
A3: 45962 | B3: 2025 | C3: 40753.45 | D3: 38267.8 | E3: 41443.1 | F3: 38007.3 | G3: 5.68B | H3: 0.065
A4: 45931 | B4: 2025 | C4: 38267.8 | D4: 36670.08 | E4: 38409.26 | F4: 36696.09 | G4: 3.51B | H4: 0.0436
A5: 45901 | B5: 2025 | C5: 36670.08 | D5: 35148.14 | E5: 36699.76 | F5: 34217.69 | G5: 2.91B | H5: 0.0433
A6: 45870 | B6: 2025 | C6: 35148.14 | D6: 34198 | E6: 36282.71 | F6: 34074.47 | G6: 3.35B | H6: 0.0278
A7: 45839 | B7: 2025 | C7: 34198 | D7: 32857.62 | E7: 34683 | F7: 32594.5 | G7: 3.58B | H7: 0.0408
A8: 45809 | B8: 2025 | C8: 32857.62 | D8: 32696.79 | E8: 33381 | F8: 29740.7 | G8: 3.41B | H8: 0.0049
A9: 45778 | B9: 2025 | C9: 32696.79 | D9: 32126.22 | E9: 32696.79 | F9: 31317.24 | G9: 3.86B | H9: 0.0178
A10: 45748 | B10: 2025 | C10: 32126.22 | D10: 32026.14 | E10: 32218.68 | F10: 29993.35 | G10: 2.48B | H10: 0.0031
A11: 45717 | B11: 2025 | C11: 32026.14 | D11: 30610.44 | E11: 32073 | F11: 30610.44 | G11: 2.75B | H11: 0.0462
A12: 45689 | B12: 2025 | C12: 30610.44 | D12: 30010.62 | E12: 31056.36 | F12: 29040.92 | G12: 2.80B | H12: 0.02 | K12: =(F2+E2) -> 83139.26
A13: 45658 | B13: 2025 | C13: 30010.62 | D13: 29740.58 | E13: 30279.95 | F13: 28349.98 | G13: 1.79B | H13: 0.0091
A14: 45627 | B14: 2024 | C14: 29740.58 | D14: 30242.13 | E14: 31232.73 | F14: 29237.94 | G14: 2.18B | H14: -0.0166
A15: 45597 | B15: 2024 | C15: 30242.13 | D15: 30658 | E15: 31799.44 | F15: 29763.65 | G15: 1.81B | H15: -0.0136
A16: 45566 | B16: 2024 | C16: 30658 | D16: 31587.04 | E16: 32184.68 | F16: 29180.44 | G16: 2.86B | H16: -0.0294
A17: 45536 | B17: 2024 | C17: 31587.04 | D17: 30774.19 | E17: 31720.84 | F17: 29803.14 | G17: 3.49B | H17: 0.0264
A18: 45505 | B18: 2024 | C18: 30774.19 | D18: 29378.82 | E18: 30910.31 | F18: 27125.63 | G18: 3.69B | H18: 0.0475
A19: 45474 | B19: 2024 | C19: 29378.82 | D19: 27766.27 | E19: 29386.84 | F19: 27766.27 | G19: 4.25B | H19: 0.0581
A20: 45444 | B20: 2024 | C20: 27766.27 | D20: 26922.76 | E20: 27938.98 | F20: 25508.57 | G20: 3.09B | H20: 0.0313
A21: 45413 | B21: 2024 | C21: 26922.76 | D21: 24448.73 | E21: 27689.14 | F21: 24193.87 | G21: 5.03B | H21: 0.1012
A22: 45383 | B22: 2024 | C22: 24448.73 | D22: 26883.39 | E22: 30072.1 | F22: 24409.83 | G22: 4.18B | H22: -0.0906
A23: 45352 | B23: 2024 | C23: 26883.39 | D23: 28964.41 | E23: 34499.42 | F23: 26746.24 | G23: 5.44B | H23: -0.0718
A24: 45323 | B24: 2024 | C24: 28964.41 | D24: 28281.91 | E24: 30035.83 | F24: 26465.07 | G24: 7.21B | H24: 0.0241
... A73: 43831 | B73: 2020 | C73: 13918.84 | D73: 13961.56 | E73: 13977.72 | F73: 13005.23 | G73: 1.33B | H73: -0.0031
A74: 43800 | B74: 2019 | C74: 13961.56 | D74: 13849.46 | E74: 14092.47 | F74: 13353.15 | G74: 1.49B | H74: 0.0081
A75: 43770 | B75: 2019 | C75: 13849.46 | D75: 14558.02 | E75: 14831.2 | F75: 13744.6 | G75: 1.41B | H75: -0.0487
A76: 43739 | B76: 2019 | C76: 14558.02 | D76: 14257.75 | E76: 14561.37 | F76: 14057.02 | G76: 2.44B | H76: 0.0211
A77: 43709 | B77: 2019 | C77: 14257.75 | D77: 14835.36 | E77: 15127.26 | F77: 13169.51 | G77: 2.43B | H77: -0.0389
A78: 43678 | B78: 2019 | C78: 14835.36 | D78: 13392.47 | E78: 14838.48 | F78: 13384.06 | G78: 2.67B | H78: 0.1077
A79: 43647 | B79: 2019 | C79: 13392.47 | D79: 14100.74 | E79: 14178.31 | F79: 13212.36 | G79: 2.71B | H79: -0.0502
A80: 43617 | B80: 2019 | C80: 14100.74 | D80: 13771.31 | E80: 14286.63 | F80: 13683.82 | G80: 1.68B | H80: 0.0239
A81: 43586 | B81: 2019 | C81: 13771.31 | D81: 14920.15 | E81: 14977.86 | F81: 13377.16 | G81: 1.42B | H81: -0.077
A82: 43556 | B82: 2019 | C82: 14920.15 | D82: 14737.88 | E82: 15262.12 | F82: 14635.35 | G82: 1.75B | H82: 0.0124
A83: 43525 | B83: 2019 | C83: 14737.88 | D83: 14803.97 | E83: 15209.09 | F83: 14469.78 | G83: 3.33B | H83: -0.0045
A84: 43497 | B84: 2019 | C84: 14803.97 | D84: 14126.68 | E84: 15321.23 | F84: 14126.68 | G84: 6.15B | H84: 0.0479
A85: 43466 | B85: 2019 | C85: 14126.68 | D85: 13035.66 | E85: 14152.11 | F85: 13035.66 | G85: 2.36B | H85: 0.0837
... A206: 39753 | B206: 2008 | C206: 4205.86 | D206: 4992.25 | E206: 5572.98 | F206: 3686.35 | G206: 75.24M | H206: -0.1082
A207: 39722 | B207: 2008 | C207: 4716.25 | D207: 7059.16 | E207: 7059.16 | F207: 4469.86 | H207: -0.3319
A208: 39692 | B208: 2008 | C208: 7059.16 | D208: 8449.56 | E208: 8509.79 | F208: 6818.66 | H208: -0.1646
...

Sheet بيانات تاريخية - عقود الفضة (3)
A1: تاريخ | B1: السنه | C1: اخر سعر | D1: سعر الفتح | E1: عالي | F1: منخفض | G1: حجم التداول | H1: التغير %
A2: 01‏/12‏/2025 | B2: 2025 | C2: 70.363 | D2: 56.64 | E2: 81.845 | F2: 56.43 | G2: 39.56K | H2: 0.2407
A3: 01‏/11‏/2025 | B3: 2025 | C3: 56.711 | D3: 48.25 | E3: 56.775 | F3: 46.52 | G3: 1.36M | H3: 0.1776
A4: 01‏/10‏/2025 | B4: 2025 | C4: 48.16 | D4: 46.735 | E4: 53.425 | F4: 45.38 | G4: 141.53K | H4: 0.0326
A5: 01‏/09‏/2025 | B5: 2025 | C5: 46.64 | D5: 40.79 | E5: 47.975 | F5: 41.065 | G5: 1.27M | H5: 0.147
A6: 01‏/08‏/2025 | B6: 2025 | C6: 40.662 | D6: 37.09 | E6: 41.995 | F6: 36.96 | G6: 1.05M | H6: 0.1076
A7: 01‏/07‏/2025 | B7: 2025 | C7: 36.712 | D7: 36.325 | E7: 39.91 | F7: 36.055 | G7: 1.15M | H7: 0.0149
A8: 01‏/06‏/2025 | B8: 2025 | C8: 36.172 | D8: 33.13 | E8: 37.405 | F8: 34.165 | G8: 1.13M | H8: 0.0822
A9: 01‏/05‏/2025 | B9: 2025 | C9: 33.423 | D9: 32.81 | E9: 33.915 | F9: 31.78 | G9: 823.23K | H9: 0.0181
A10: 01‏/04‏/2025 | B10: 2025 | C10: 32.828 | D10: 34.77 | E10: 35.155 | F10: 29.115 | G10: 1.28M | H10: -0.0515
A11: 01‏/03‏/2025 | B11: 2025 | C11: 34.611 | D11: 31.715 | E11: 35.495 | F11: 32.03 | G11: 982.64K | H11: 0.0779
A12: 01‏/02‏/2025 | B12: 2025 | C12: 32.11 | D12: 32.46 | E12: 34.24 | F12: 31.365 | G12: 961.43K | H12: -0.0118
A13: 01‏/01‏/2025 | B13: 2025 | C13: 32.493 | D13: 29.31 | E13: 32.92 | F13: 29.935 | G13: 811.87K | H13: 0.1048
... A313: 01‏/01‏/2000 | B313: 2000 | C313: 5.321 | D313: 5.42 | E313: 5.47 | F313: 5.125 | G313: 204.63K | H313: -0.0242

Sheet بيانات تاريخية - عقود الذهب
A1: تاريخ | B1: السنه | C1: اخر سعر | D1: سعر الفتح | E1: عالي | F1: منخفض | G1: حجم التداول | H1: التغير %
A2: 01‏/12‏/2025 | B2: 2025 | C2: 4357.1 | D2: 4258.5 | E2: 4584 | F2: 4194 | G2: 4.15M | H2: 0.024
A3: 01‏/11‏/2025 | B3: 2025 | C3: 4254.9 | D3: 4014.9 | E3: 4264.4 | F3: 3954.3 | G3: 363.28K | H3: 0.0602
A4: 01‏/10‏/2025 | B4: 2025 | C4: 4013.3 | D4: 3887.7 | E4: 4398 | F4: 3842.8 | G4: 7.37M | H4: 0.0362
A5: 01‏/09‏/2025 | B5: 2025 | C5: 3873.2 | D5: 3517.9 | E5: 3899.2 | F5: 3506 | G5: 3.97M | H5: 0.1028
A6: 01‏/08‏/2025 | B6: 2025 | C6: 3512 | D6: 3416.6 | E6: 3517.65 | F6: 3353.4 | G6: 3.12M | H6: 0.0488
A7: 01‏/07‏/2025 | B7: 2025 | C7: 3348.6 | D7: 3315.7 | E7: 3509 | F7: 3290.2 | G7: 3.59M | H7: 0.0124
A8: 01‏/06‏/2025 | B8: 2025 | C8: 3307.7 | D8: 3323 | E8: 3476.3 | F8: 3250.5 | G8: 3.18M | H8: -0.0108
A9: 01‏/05‏/2025 | B9: 2025 | C9: 3343.9 | D9: 3299 | E9: 3448.2 | F9: 3123.3 | G9: 4.06M | H9: 0.0075
A10: 01‏/04‏/2025 | B10: 2025 | C10: 3319.1 | D10: 3157.3 | E10: 3509.9 | F10: 2970.4 | G10: 4.42M | H10: 0.0536
A11: 01‏/03‏/2025 | B11: 2025 | C11: 3150.3 | D11: 2872 | E11: 3162 | F11: 2866.3 | G11: 3.15M | H11: 0.0878
A12: 01‏/02‏/2025 | B12: 2025 | C12: 2895.9 | D12: 2846.5 | E12: 2973.4 | F12: 2802.2 | G12: 2.81M | H12: 0.0178
A13: 01‏/01‏/2025 | B13: 2025 | C13: 2845.2 | D13: 2641 | E13: 2853.2 | F13: 2624.6 | G13: 2.86M | H13: 0.0867
... A313: 01‏/01‏/2000 | B313: 2000 | C313: 286.2 | D313: 289.5 | E313: 291.8 | F313: 280 | G313: 414.02K | H313: -0.0117

Sheet البيانات التاريخية للدولار 
A1: التاريخ | B1: العملة | C1: بيع
A2: 45992 | B2: دولار أمريكى | C2: 47.6006
A3: 38355 | B3: دولار أمريكى | C3: 6.0745
A4: 38356 | B4: دولار أمريكى | C4: 6.045
A5: 38357 | B5: دولار أمريكى | C5: 6.0019
A6: 38358 | B6: دولار أمريكى | C6: 5.9854
A7: 38361 | B7: دولار أمريكى | C7: 5.9758
A8: 38362 | B8: دولار أمريكى | C8: 5.9601
A9: 38363 | B9: دولار أمريكى | C9: 5.9414
A10: 38364 | B10: دولار أمريكى | C10: 5.9318
A11: 38365 | B11: دولار أمريكى | C11: 5.9234
A12: 38368 | B12: دولار أمريكى | C12: 5.9076
A13: 38369 | B13: دولار أمريكى | C13: 5.8955
... A5029: 46022 | B5029: دولار أمريكى | C5029: 47.7381

Sheet البيانات التاريخيه لليورو 
A1: التاريخ | B1: العملة | C1: شراء | D1: بيع
A2: 46022 | B2: يورو | C2: 55.9255 | D2: 56.0923
A3: 46021 | B3: يورو | C3: 56.0196 | D3: 56.1794
A4: 46020 | B4: يورو | C4: 56.0569 | D4: 56.2179
A5: 46019 | B5: يورو | C5: 56.0169 | D5: 56.1931
A6: 46016 | B6: يورو | C6: 56.0016 | D6: 56.1864
A7: 46015 | B7: يورو | C7: 56.0329 | D7: 56.2076
A8: 46014 | B8: يورو | C8: 55.9909 | D8: 56.1568
A9: 46013 | B9: يورو | C9: 55.6216 | D9: 55.788
A10: 46012 | B10: يورو | C10: 55.5839 | D10: 55.7601
A11: 46009 | B11: يورو | C11: 55.7015 | D11: 55.863
A12: 46008 | B12: يورو | C12: 55.6488 | D12: 55.8149
A13: 46007 | B13: يورو | C13: 55.6939 | D13: 55.8627
... A266: 45628 | B266: يورو | C266: 52.2249 | D266: 52.377
A267: 45658 | B267: يورو | D267: 52.85
A268: 45624 | B268: يورو | C268: 52.2419 | D268: 52.3928
A269: 45623 | B269: يورو | C269: 52.2165 | D269: 52.3679
A270: 45622 | B270: يورو | C270: 52.0585 | D270: 52.2067
A271: 45621 | B271: يورو | C271: 51.9302 | D271: 52.0725
A272: 45620 | B272: يورو | C272: 51.6634 | D272: 51.8183
A273: 45617 | B273: يورو | C273: 52.1956 | D273: 52.3464
A274: 45616 | B274: يورو | C274: 52.4261 | D274: 52.5859
A275: 45615 | B275: يورو | C275: 52.2446 | D275: 52.3966
A276: 45614 | B276: يورو | C276: 52.0362 | D276: 52.1861
A277: 45613 | B277: يورو | C277: 51.9766 | D277: 52.1252
A278: 45610 | B278: يورو | C278: 51.9047 | D278: 52.0592
A279: 45609 | B279: يورو | C279: 52.4079 | D279: 52.5561
... A5030: 38354 | B5030: يورو | C5030: 8.2864 | D5030: 8.3154

Sheet الفضه
A1: التاريخ | B1: السنه | C1: سعر الفضة | D1: سعر الذهب | E1: مؤشر البورصه المصرية
A2: 45992 | B2: 2025 | C2: 70.363 | D2: 4357.1 | E2: 42624.11
A3: 45962 | B3: 2025 | C3: 56.711 | D3: 4254.9 | E3: 41443.1
A4: 45931 | B4: 2025 | C4: 48.16 | D4: 4013.3 | E4: 38409.26
A5: 45901 | B5: 2025 | C5: 46.64 | D5: 3873.2 | E5: 36699.76
A6: 45870 | B6: 2025 | C6: 40.662 | D6: 3512 | E6: 36282.71
A7: 45839 | B7: 2025 | C7: 36.712 | D7: 3348.6 | E7: 34683
A8: 45809 | B8: 2025 | C8: 36.172 | D8: 3307.7 | E8: 33381
A9: 45778 | B9: 2025 | C9: 33.423 | D9: 3343.9 | E9: 32696.79
A10: 45748 | B10: 2025 | C10: 32.828 | D10: 3319.1 | E10: 32218.68
A11: 45717 | B11: 2025 | C11: 34.611 | D11: 3150.3 | E11: 32073
A12: 45689 | B12: 2025 | C12: 32.11 | D12: 2895.9 | E12: 31056.36
A13: 45658 | B13: 2025 | C13: 32.493 | D13: 2845.2 | E13: 30279.95
... A179: 40603 | B179: 2011 | C179: 37.9 | D179: 1439.9 | E179: 5605.4
A180: 40575 | B180: 2011 | C180: 33.82 | D180: 1409.9 | E180: =(E181+E179)/2 -> 6426.675
A181: 40544 | B181: 2011 | C181: 28.179 | D181: 1334.5 | E181: 7247.95
A182: 40513 | B182: 2010 | C182: 30.937 | D182: 1421.4 | E182: 7148.77
A183: 40483 | B183: 2010 | C183: 28.199 | D183: 1386.1 | E183: 7008.9
A184: 40452 | B184: 2010 | C184: 24.585 | D184: 1357.6 | E184: 6947.67
A185: 40422 | B185: 2010 | C185: 21.821 | D185: 1309.6 | E185: 6781.26
A186: 40391 | B186: 2010 | C186: 19.418 | D186: 1250.3 | E186: 6521.18
A187: 40360 | B187: 2010 | C187: 18.02 | D187: 1183.9 | E187: 6316.52
A188: 40330 | B188: 2010 | C188: 18.708 | D188: 1245.9 | E188: 6601.19
A189: 40299 | B189: 2010 | C189: 18.44 | D189: 1215 | E189: 7451.09
A190: 40269 | B190: 2010 | C190: 18.639 | D190: 1180.7 | E190: 7693.46
A191: 40238 | B191: 2010 | C191: 17.54 | D191: 1114.5 | E191: 6896.6
A192: 40210 | B192: 2010 | C192: 16.521 | D192: 1118.9 | E192: 7076.6
... A253: 38353 | B253: 2005 | C253: 6.762 | D253: 424.1 | E253: 3538.51

Sheet data set 1 
A1: التاريخ | B1: السنه | C1: سعر اليورو | D1: نسبة التغير السنوية | E1: نسبه التغير لليورو التاريخية لتاريخيه على مدار 20 سنة | F1: سعر الدولار | G1: نسبه التغير للدولار على مدار 20 سنة | H1: سعر الفضة | I1: نسبه التغير الفضه التاريخيه على مدار 20 سنة | J1: سعر الذهب | K1: نسبه التغير الذهب على مدار 20 سنة | L1: مؤشر البورصه المصرية | M1: نسبه التغير المؤشر الرئيسى للبورصه لتاريخيه على مدار 20 سنة | N1: متوسط النمو يورو | O1: متوسط النمو دولار | P1: متوسط النمو فضة | Q1: متوسط النمو ذهب | R1: متوسط النمو بورصة
A2: 45992 | B2: 2025 | C2: 55.3642 | D2: =Table1_2[[#This Row],[سعر اليورو ]]/C3 -> 1.0145482 | E2: =Table1_2[[#This Row],[سعر اليورو ]]/$C$253 -> 6.6580321 | F2: 47.6006 | G2: =Table1_2[[#This Row],[سعر الدولار ]]/$F$253 -> 7.7897131 | H2: 70.363 | I2: =Table1_2[[#This Row],[سعر الفضة ]]/$H$253 -> 10.405649 | J2: 4357.1 | K2: =Table1_2[[#This Row],[سعر الذهب ]]/$J$253 -> 10.273756 | L2: 42624.11 | M2: =Table1_2[[#This Row],[مؤشر البورصه المصرية ]]/$L$253 -> 12.045779 | N2: =(Table1_2[[#This Row],[سعر اليورو ]]/$C$253)^1/20 -> 0.3329016 | O2: =(Table1_2[[#This Row],[سعر الدولار ]]/$F$253)^1/20 -> 0.38948566 | P2: =(Table1_2[[#This Row],[سعر الفضة ]]/$H$253)^1/20 -> 0.52028246 | Q2: =(Table1_2[[#This Row],[سعر الذهب ]]/$J$253)^1/20 -> 0.51368781 | R2: =((Table1_2[[#This Row],[مؤشر البورصه المصرية ]]/$L$253)^1/20) -1 -> -0.39771104
A3: 45962 | B3: 2025 | C3: 54.5703 | D3: =Table1_2[[#This Row],[سعر اليورو ]]/C4 -> 0.97092058 | E3: =Table1_2[[#This Row],[سعر اليورو ]]/$C$253 -> 6.5625586 | F3: 47.3003 | G3: =Table1_2[[#This Row],[سعر الدولار ]]/$F$253 -> 7.7405698 | H3: 56.711 | I3: =Table1_2[[#This Row],[سعر الفضة ]]/$H$253 -> 8.3867199 | J3: 4254.9 | K3: =Table1_2[[#This Row],[سعر الذهب ]]/$J$253 -> 10.032775 | L3: 41443.1 | M3: =Table1_2[[#This Row],[مؤشر البورصه المصرية ]]/$L$253 -> 11.71202 | N3: =(Table1_2[[#This Row],[سعر اليورو ]]/$C$253)^1/20 -> 0.32812793 | O3: =(Table1_2[[#This Row],[سعر الدولار ]]/$F$253)^1/20 -> 0.38702849 | P3: =(Table1_2[[#This Row],[سعر الفضة ]]/$H$253)^1/20 -> 0.419336 | Q3: =(Table1_2[[#This Row],[سعر الذهب ]]/$J$253)^1/20 -> 0.50163876 | R3: =((Table1_2[[#This Row],[مؤشر البورصه المصرية ]]/$L$253)^1/20) -1 -> -0.414399
A4: 45931 | B4: 2025 | C4: 56.2047 | D4: =Table1_2[[#This Row],[سعر اليورو ]]/C5 -> 0.9857672 | E4: =Table1_2[[#This Row],[سعر اليورو ]]/$C$253 -> 6.7591096 | F4: 47.9276 | G4: =Table1_2[[#This Row],[سعر الدولار ]]/$F$253 -> 7.8432258 | H4: 48.16 | I4: =Table1_2[[#This Row],[سعر الفضة ]]/$H$253 -> 7.1221532 | J4: 4013.3 | K4: =Table1_2[[#This Row],[سعر الذهب ]]/$J$253 -> 9.4630983 | L4: 38409.26 | M4: =Table1_2[[#This Row],[مؤشر البورصه المصرية ]]/$L$253 -> 10.854642 | N4: =(Table1_2[[#This Row],[سعر اليورو ]]/$C$253)^1/20 -> 0.33795548 | O4: =(Table1_2[[#This Row],[سعر الدولار ]]/$F$253)^1/20 -> 0.39216129 | P4: =(Table1_2[[#This Row],[سعر الفضة ]]/$H$253)^1/20 -> 0.35610766 | Q4: =(Table1_2[[#This Row],[سعر الذهب ]]/$J$253)^1/20 -> 0.47315492 | R4: =((Table1_2[[#This Row],[مؤشر البورصه المصرية ]]/$L$253)^1/20) -1 -> -0.45726789
A5: 45901 | B5: 2025 | C5: 57.0162 | D5: =Table1_2[[#This Row],[سعر اليورو ]]/C6 -> 1.0102717 | E5: =Table1_2[[#This Row],[سعر اليورو ]]/$C$253 -> 6.8566996 | F5: 48.6279 | G5: =Table1_2[[#This Row],[سعر الدولار ]]/$F$253 -> 7.9578281 | H5: 46.64 | I5: =Table1_2[[#This Row],[سعر الفضة ]]/$H$253 -> 6.8973676 | J5: 3873.2 | K5: =Table1_2[[#This Row],[سعر الذهب ]]/$J$253 -> 9.1327517 | L5: 36699.76 | M5: =Table1_2[[#This Row],[مؤشر البورصه المصرية ]]/$L$253 -> 10.371529 | N5: =(Table1_2[[#This Row],[سعر اليورو ]]/$C$253)^1/20 -> 0.34283498 | O5: =(Table1_2[[#This Row],[سعر الدولار ]]/$F$253)^1/20 -> 0.3978914 | P5: =(Table1_2[[#This Row],[سعر الفضة ]]/$H$253)^1/20 -> 0.34486838 | Q5: =(Table1_2[[#This Row],[سعر الذهب ]]/$J$253)^1/20 -> 0.45663759 | R5: =((Table1_2[[#This Row],[مؤشر البورصه المصرية ]]/$L$253)^1/20) -1 -> -0.48142354
A6: 45870 | B6: 2025 | C6: 56.4365 | D6: =Table1_2[[#This Row],[سعر اليورو ]]/C7 -> 0.96480401 | E6: =Table1_2[[#This Row],[سعر اليورو ]]/$C$253 -> 6.7869856 | F6: 48.7067 | G6: =Table1_2[[#This Row],[سعر الدولار ]]/$F$253 -> 7.9707235 | H6: 40.662 | I6: =Table1_2[[#This Row],[سعر الفضة ]]/$H$253 -> 6.0133097 | J6: 3512 | K6: =Table1_2[[#This Row],[سعر الذهب ]]/$J$253 -> 8.2810658 | L6: 36282.71 | M6: =Table1_2[[#This Row],[مؤشر البورصه المصرية ]]/$L$253 -> 10.253669 | N6: =(Table1_2[[#This Row],[سعر اليورو ]]/$C$253)^1/20 -> 0.33934928 | O6: =(Table1_2[[#This Row],[سعر الدولار ]]/$F$253)^1/20 -> 0.39853617 | P6: =(Table1_2[[#This Row],[سعر الفضة ]]/$H$253)^1/20 -> 0.30066548 | Q6: =(Table1_2[[#This Row],[سعر الذهب ]]/$J$253)^1/20 -> 0.41405329 | R6: =((Table1_2[[#This Row],[مؤشر البورصه المصرية ]]/$L$253)^1/20) -1 -> -0.48731655
A7: 45839 | B7: 2025 | C7: 58.4953 | D7: =Table1_2[[#This Row],[سعر اليورو ]]/C8 -> 1.0356817 | E7: =Table1_2[[#This Row],[سعر اليورو ]]/$C$253 -> 7.0345744 | F7: 49.5177 | G7: =Table1_2[[#This Row],[سعر الدولار ]]/$F$253 -> 8.1034415 | H7: 36.712 | I7: =Table1_2[[#This Row],[سعر الفضة ]]/$H$253 -> 5.429163 | J7: 3348.6 | K7: =Table1_2[[#This Row],[سعر الذهب ]]/$J$253 -> 7.8957793 | L7: 34683 | M7: =Table1_2[[#This Row],[مؤشر البورصه المصرية ]]/$L$253 -> 9.8015832 | N7: =(Table1_2[[#This Row],[سعر اليورو ]]/$C$253)^1/20 -> 0.35172872 | O7: =(Table1_2[[#This Row],[سعر الدولار ]]/$F$253)^1/20 -> 0.40517208 | P7: =(Table1_2[[#This Row],[سعر الفضة ]]/$H$253)^1/20 -> 0.27145815 | Q7: =(Table1_2[[#This Row],[سعر الذهب ]]/$J$253)^1/20 -> 0.39478896 | R7: =((Table1_2[[#This Row],[مؤشر البورصه المصرية ]]/$L$253)^1/20) -1 -> -0.50992084
A8: 45809 | B8: 2025 | C8: 56.48 | D8: =Table1_2[[#This Row],[سعر اليورو ]]/C9 -> 0.98448838 | E8: =Table1_2[[#This Row],[سعر اليورو ]]/$C$253 -> 6.7922169 | F8: 49.7665 | G8: =Table1_2[[#This Row],[سعر الدولار ]]/$F$253 -> 8.144157 | H8: 36.172 | I8: =Table1_2[[#This Row],[سعر الفضة ]]/$H$253 -> 5.3493049 | J8: 3307.7 | K8: =Table1_2[[#This Row],[سعر الذهب ]]/$J$253 -> 7.7993398 | L8: 33381 | M8: =Table1_2[[#This Row],[مؤشر البورصه المصرية ]]/$L$253 -> 9.4336317 | N8: =(Table1_2[[#This Row],[سعر اليورو ]]/$C$253)^1/20 -> 0.33961084 | O8: =(Table1_2[[#This Row],[سعر الدولار ]]/$F$253)^1/20 -> 0.40720785 | P8: =(Table1_2[[#This Row],[سعر الفضة ]]/$H$253)^1/20 -> 0.26746525 | Q8: =(Table1_2[[#This Row],[سعر الذهب ]]/$J$253)^1/20 -> 0.38996699 | R8: =((Table1_2[[#This Row],[مؤشر البورصه المصرية ]]/$L$253)^1/20) -1 -> -0.52831842
A9: 45778 | B9: 2025 | C9: 57.3699 | D9: =Table1_2[[#This Row],[سعر اليورو ]]/C10 -> 1.0208204 | E9: =Table1_2[[#This Row],[سعر اليورو ]]/$C$253 -> 6.8992352 | F9: 50.7833 | G9: =Table1_2[[#This Row],[سعر الدولار ]]/$F$253 -> 8.3105536 | H9: 33.423 | I9: =Table1_2[[#This Row],[سعر الفضة ]]/$H$253 -> 4.9427684 | J9: 3343.9 | K9: =Table1_2[[#This Row],[سعر الذهب ]]/$J$253 -> 7.884697 | L9: 32696.79 | M9: =Table1_2[[#This Row],[مؤشر البورصه المصرية ]]/$L$253 -> 9.2402706 | N9: =(Table1_2[[#This Row],[سعر اليورو ]]/$C$253)^1/20 -> 0.34496176 | O9: =(Table1_2[[#This Row],[سعر الدولار ]]/$F$253)^1/20 -> 0.41552768 | P9: =(Table1_2[[#This Row],[سعر الفضة ]]/$H$253)^1/20 -> 0.24713842 | Q9: =(Table1_2[[#This Row],[سعر الذهب ]]/$J$253)^1/20 -> 0.39423485 | R9: =((Table1_2[[#This Row],[مؤشر البورصه المصرية ]]/$L$253)^1/20) -1 -> -0.53798647
A10: 45748 | B10: 2025 | C10: 56.1998 | D10: =Table1_2[[#This Row],[سعر اليورو ]]/C11 -> 1.0677167 | E10: =Table1_2[[#This Row],[سعر اليورو ]]/$C$253 -> 6.7585203 | F10: 50.6669 | G10: =Table1_2[[#This Row],[سعر الدولار ]]/$F$253 -> 8.2915051 | H10: 32.828 | I10: =Table1_2[[#This Row],[سعر الفضة ]]/$H$253 -> 4.8547767 | J10: 3319.1 | K10: =Table1_2[[#This Row],[سعر الذهب ]]/$J$253 -> 7.8262202 | L10: 32218.68 | M10: =Table1_2[[#This Row],[مؤشر البورصه المصرية ]]/$L$253 -> 9.1051544 | N10: =(Table1_2[[#This Row],[سعر اليورو ]]/$C$253)^1/20 -> 0.33792602 | O10: =(Table1_2[[#This Row],[سعر الدولار ]]/$F$253)^1/20 -> 0.41457525 | P10: =(Table1_2[[#This Row],[سعر الفضة ]]/$H$253)^1/20 -> 0.24273883 | Q10: =(Table1_2[[#This Row],[سعر الذهب ]]/$J$253)^1/20 -> 0.39131101 | R10: =((Table1_2[[#This Row],[مؤشر البورصه المصرية ]]/$L$253)^1/20) -1 -> -0.54474228
A11: 45717 | B11: 2025 | C11: 52.6355 | D11: =Table1_2[[#This Row],[سعر اليورو ]]/C12 -> 1.0096233 | E11: =Table1_2[[#This Row],[سعر اليورو ]]/$C$253 -> 6.3298819 | F11: 50.7232 | G11: =Table1_2[[#This Row],[سعر الدولار ]]/$F$253 -> 8.3007184 | H11: 34.611 | I11: =Table1_2[[#This Row],[سعر الفضة ]]/$H$253 -> 5.1184561 | J11: 3150.3 | K11: =Table1_2[[#This Row],[سعر الذهب ]]/$J$253 -> 7.4282009 | L11: 32073 | M11: =Table1_2[[#This Row],[مؤشر البورصه المصرية ]]/$L$253 -> 9.0639846 | N11: =(Table1_2[[#This Row],[سعر اليورو ]]/$C$253)^1/20 -> 0.3164941 | O11: =(Table1_2[[#This Row],[سعر الدولار ]]/$F$253)^1/20 -> 0.41503592 | P11: =(Table1_2[[#This Row],[سعر الفضة ]]/$H$253)^1/20 -> 0.2559228 | Q11: =(Table1_2[[#This Row],[سعر الذهب ]]/$J$253)^1/20 -> 0.37141004 | R11: =((Table1_2[[#This Row],[مؤشر البورصه المصرية ]]/$L$253)^1/20) -1 -> -0.54680077
A12: 45689 | B12: 2025 | C12: 52.1338 | D12: =Table1_2[[#This Row],[سعر اليورو ]]/C13 -> 0.98644844 | E12: =Table1_2[[#This Row],[سعر اليورو ]]/$C$253 -> 6.2695481 | F12: 50.2979 | G12: =Table1_2[[#This Row],[سعر الدولار ]]/$F$253 -> 8.2311192 | H12: 32.11 | I12: =Table1_2[[#This Row],[سعر الفضة ]]/$H$253 -> 4.7485951 | J12: 2895.9 | K12: =Table1_2[[#This Row],[سعر الذهب ]]/$J$253 -> 6.8283424 | L12: 31056.36 | M12: =Table1_2[[#This Row],[مؤشر البورصه المصرية ]]/$L$253 -> 8.7766772 | N12: =(Table1_2[[#This Row],[سعر اليورو ]]/$C$253)^1/20 -> 0.3134774 | O12: =(Table1_2[[#This Row],[سعر الدولار ]]/$F$253)^1/20 -> 0.41155596 | P12: =(Table1_2[[#This Row],[سعر الفضة ]]/$H$253)^1/20 -> 0.23742975 | Q12: =(Table1_2[[#This Row],[سعر الذهب ]]/$J$253)^1/20 -> 0.34141712 | R12: =((Table1_2[[#This Row],[مؤشر البورصه المصرية ]]/$L$253)^1/20) -1 -> -0.56116614
A13: 45658 | B13: 2025 | C13: 52.85 | D13: =Table1_2[[#This Row],[سعر اليورو ]]/C14 -> 1.0061358 | E13: =Table1_2[[#This Row],[سعر اليورو ]]/$C$253 -> 6.3556774 | F13: 50.8407 | G13: =Table1_2[[#This Row],[سعر الدولار ]]/$F$253 -> 8.319947 | H13: 32.493 | I13: =Table1_2[[#This Row],[سعر الفضة ]]/$H$253 -> 4.8052351 | J13: 2845.2 | K13: =Table1_2[[#This Row],[سعر الذهب ]]/$J$253 -> 6.7087951 | L13: 30279.95 | M13: =Table1_2[[#This Row],[مؤشر البورصه المصرية ]]/$L$253 -> 8.55726 | N13: =(Table1_2[[#This Row],[سعر اليورو ]]/$C$253)^1/20 -> 0.31778387 | O13: =(Table1_2[[#This Row],[سعر الدولار ]]/$F$253)^1/20 -> 0.41599735 | P13: =(Table1_2[[#This Row],[سعر الفضة ]]/$H$253)^1/20 -> 0.24026176 | Q13: =(Table1_2[[#This Row],[سعر الذهب ]]/$J$253)^1/20 -> 0.33543975 | R13: =((Table1_2[[#This Row],[مؤشر البورصه المصرية ]]/$L$253)^1/20) -1 -> -0.572137
... A253: 38353 | B253: 2005 | C253: 8.3154 | D253: =Table1_2[[#This Row],[سعر اليورو ]]/C254 -> #DIV/0! | E253: =Table1_2[[#This Row],[سعر اليورو ]]/$C$253 -> 1 | F253: 6.1107 | G253: =Table1_2[[#This Row],[سعر الدولار ]]/$F$253 -> 1 | H253: 6.762 | I253: =Table1_2[[#This Row],[سعر الفضة ]]/$H$253 -> 1 | J253: 424.1 | K253: =Table1_2[[#This Row],[سعر الذهب ]]/$J$253 -> 1 | L253: 3538.51 | M253: =Table1_2[[#This Row],[مؤشر البورصه المصرية ]]/$L$253 -> 1 | N253: =(Table1_2[[#This Row],[سعر اليورو ]]/$C$253)^1/20 -> 0.05 | O253: =(Table1_2[[#This Row],[سعر الدولار ]]/$F$253)^1/20 -> 0.05 | P253: =(Table1_2[[#This Row],[سعر الفضة ]]/$H$253)^1/20 -> 0.05 | Q253: =(Table1_2[[#This Row],[سعر الذهب ]]/$J$253)^1/20 -> 0.05 | R253: =((Table1_2[[#This Row],[مؤشر البورصه المصرية ]]/$L$253)^1/20) -1 -> -0.95
L257: =L2/L253 -> 12.045779

Sheet Sheet2
A3: Row Labels
A4: (blank)

Sheet Table1
A1: التاريخ | B1: السنه | C1: سعر الفضة | D1: سعر الذهب | E1: مؤشر البورصه المصرية
A2: 45992 | B2: 2025 | C2: 70.363 | D2: 4357.1 | E2: 42624.11
A3: 45962 | B3: 2025 | C3: 56.711 | D3: 4254.9 | E3: 41443.1
A4: 45931 | B4: 2025 | C4: 48.16 | D4: 4013.3 | E4: 38409.26
A5: 45901 | B5: 2025 | C5: 46.64 | D5: 3873.2 | E5: 36699.76
A6: 45870 | B6: 2025 | C6: 40.662 | D6: 3512 | E6: 36282.71
A7: 45839 | B7: 2025 | C7: 36.712 | D7: 3348.6 | E7: 34683
A8: 45809 | B8: 2025 | C8: 36.172 | D8: 3307.7 | E8: 33381
A9: 45778 | B9: 2025 | C9: 33.423 | D9: 3343.9 | E9: 32696.79
A10: 45748 | B10: 2025 | C10: 32.828 | D10: 3319.1 | E10: 32218.68
A11: 45717 | B11: 2025 | C11: 34.611 | D11: 3150.3 | E11: 32073
A12: 45689 | B12: 2025 | C12: 32.11 | D12: 2895.9 | E12: 31056.36
A13: 45658 | B13: 2025 | C13: 32.493 | D13: 2845.2 | E13: 30279.95
... A253: 38353 | B253: 2005 | C253: 6.762 | D253: 424.1 | E253: 3538.51

Sheet analysis  1 
A3: السنه | B3: نسبه التغير المؤشر الرئيسى للبورصه لتاريخيه على مدار 20 سنة | C3: نسبه التغير الذهب على مدار 20 سنة | D3: نسبه التغير للدولار على مدار 20 سنة | E3: نسبه التغير الفضه التاريخيه على مدار 20 سنة | F3: نسبه التغير لليورو التاريخية لتاريخيه على مدار 20 سنة
A4: 2005 | B4: 1.4017727 | C4: 1.064293 | D4: 0.95218497 | E4: 1.100944 | F4: 0.87749737
A5: 2006 | B5: 1.9259175 | C5: 1.4596597 | D5: 0.94105013 | E5: 1.7693976 | F5: 0.86646563
A6: 2007 | B6: 2.3755024 | C6: 1.676904 | D6: 0.92596593 | E6: 2.0165139 | F6: 0.92998332
A7: 2008 | B7: 2.6924221 | C7: 2.0768687 | D7: 0.89194637 | E7: 2.2225919 | F7: 0.96247525
A8: 2009 | B8: 1.684381 | C8: 2.3249823 | D8: 0.91098538 | E8: 2.1861136 | F8: 0.93265207
A9: 2010 | B9: 1.9629774 | C9: 2.9214218 | D9: 0.92236841 | E9: 3.0689638 | F9: 0.90306941
A10: 2011 | B10: 1.518913 | C10: 3.7152794 | D10: 0.97358595 | E10: 5.2823745 | F10: 1.0018339
A11: 2012 | B11: 1.5010068 | C11: 3.9573803 | D11: 0.99394777 | E11: 4.641329 | F11: 0.94117541
A12: 2013 | B12: 1.6458752 | C12: 3.2887487 | D12: 1.1282491 | E12: 3.4531081 | F12: 1.1006646
A13: 2014 | B13: 2.526538 | C13: 2.9517606 | D13: 1.1578911 | E13: 2.7517623 | F13: 1.1353342
A14: 2015 | B14: 2.4358685 | C14: 2.7173623 | D14: 1.2503505 | E14: 2.2944765 | F14: 1.0180148
A15: 2016 | B15: 2.408432 | C15: 2.9473591 | D15: 1.5226433 | E15: 2.5347037 | F15: 1.2373969
... A24: 2025 | B24: 9.9346834 | C24: 8.2962352 | D24: 8.0836252 | E24: 6.1727916 | F24: 6.67192
A34: السنه | B34: نسبه التغير المؤشر الرئيسى للبورصه لتاريخيه على مدار 20 سنة | C34: نسبه التغير التراكمية للذهب على مدار 20 سنة | D34: نسبه التغير التراكمية للدولار على مدار 20 سنة | E34: نسبه التغير التراكمية الفضه التاريخيه على مدار 20 سنة | F34: نسبه التغير التراكمية لليورو على مدار 20 سنة
A35: 2025 | B35: 9.9346834 | C35: 8.2962352 | D35: 8.0836252 | E35: 6.1727916 | F35: 6.67192
A52: السنه | B52: Max of سعر الفضة
A53: 2005 | B53: 8.89
A54: 2006 | B54: 14.052 | X54: =100*1205 -> 120500
A55: 2007 | B55: 14.92
A56: 2008 | B56: 19.915
A57: 2009 | B57: 18.517
A58: 2010 | B58: 30.937
A59: 2011 | B59: 48.599
A60: 2012 | B60: 34.642
A61: 2013 | B61: 31.38
A62: 2014 | B62: 21.241
A63: 2015 | B63: 17.228
A64: 2016 | B64: 20.393
A65: 2017 | B65: 18.469
A66: 2018 | B66: 17.284
... A73: 2025 | B73: 70.363
A74: Grand Total | B74: 70.363
A81: Row Labels | B81: Max of سعر الذهب
A82: 2005 | B82: 519.7
A83: 2006 | B83: 654.5
A84: 2007 | B84: 838
A85: 2008 | B85: 975
A86: 2009 | B86: 1182.3
A87: 2010 | B87: 1421.4
...

Sheet Detail1
A1: Details for Sum of نسبة التغير السنوية لليورو - السنه : 2007
A3: التاريخ | B3: السنه | C3: سعر اليورو | D3: نسبة التغير السنوية لليورو | E3: الانحراف المعياري لليورو | F3: نسبه التغير لليورو التاريخية | G3: سعر الدولار | H3: نسبة التغير السنوية الدولار | I3: الانحراف المعياري للدولار | J3: متوسط نسبه التغير للدولار التراكمية | K3: سعر الفضة | L3: نسبة التغير السنوية للفضه | M3: الانحراف المعياري للفضه | N3: نسبه التغير الفضه | O3: سعر الذهب | P3: نسبة التغير السنوية للذهب | Q3: الانحراف المعياري للذهب | R3: نسبه التغير الذهب | S3: مؤشر البورصه المصرية | T3: نسبة التغير السنوية للمؤشر الرئيسى للبورصه المصرية EGX30 | U3: الانحراف المعياري للمؤشر الرئيسى للبورصة المصرية EGX30 | V3: نسبه التغير المؤشر الرئيسى للبورصه | W3: Column1
A4: 39417 | B4: 2007 | C4: 8.1098 | D4: 0.061672798 | F4: 0.92998332 | G4: 5.5406 | H4: -0.032327925 | J4: 0.92596593 | K4: 14.92 | L4: 0.15345961 | N4: 2.0165139 | O4: 838 | P4: 0.31347962 | R4: 1.676904 | S4: 10549.74 | T4: 0.51265933 | V4: 2.3755024
H28: موشر EXG 30 حقق اعلى نمو تاريخى . الفضة شهدت تقلبات قوية بعد 2020 الدولار ارتفع بشكل حاد فى 2024 -2025 الذهب هو الاكثر استقرار فى الاصول الاستثمارية

Sheet Detail2
A1: Details for Sum of نسبة التغير السنوية لليورو - السنه : 2006
A3: التاريخ | B3: السنه | C3: سعر اليورو | D3: نسبة التغير السنوية لليورو | E3: الانحراف المعياري لليورو | F3: نسبه التغير لليورو التاريخية | G3: سعر الدولار | H3: نسبة التغير السنوية الدولار | I3: الانحراف المعياري للدولار | J3: متوسط نسبه التغير للدولار التراكمية | K3: سعر الفضة | L3: نسبة التغير السنوية للفضه | M3: الانحراف المعياري للفضه | N3: نسبه التغير الفضه | O3: سعر الذهب | P3: نسبة التغير السنوية للذهب | Q3: الانحراف المعياري للذهب | R3: نسبه التغير الذهب | S3: مؤشر البورصه المصرية | T3: نسبة التغير السنوية للمؤشر الرئيسى للبورصه المصرية EGX30 | U3: الانحراف المعياري للمؤشر الرئيسى للبورصة المصرية EGX30 | V3: نسبه التغير المؤشر الرئيسى للبورصه | W3: Column1
A4: 39052 | B4: 2006 | C4: 7.6387 | D4: 0.12476073 | F4: 0.86646563 | G4: 5.7257 | H4: -0.0074368131 | J4: 0.94105013 | K4: 12.935 | L4: 0.45500562 | N4: 1.7693976 | O4: 638 | P4: 0.22763133 | R4: 1.4596597 | S4: 6974.3 | T4: 0.10178341 | V4: 1.9259175

Sheet analysis 2 
A1: التاريخ | B1: السنه | C1: سعر اليورو | D1: نسبة التغير السنوية لليورو | E1: الانحراف المعياري | F1: نسبه التغير لليورو التاريخية | G1: سعر الدولار | H1: نسبة التغير السنوية الدولار | I1: الانحراف المعياري2 | J1: نسبه التغير للدولار | K1: سعر الفضة | L1: نسبة التغير السنوية للفضه | M1: الانحراف المعياري3 | N1: نسبه التغير الفضه | O1: سعر الذهب | P1: نسبة التغير السنوية للذهب | Q1: الانحراف المعياري للذهب | R1: نسبه التغير الذهب | S1: مؤشر البورصه المصرية | T1: نسبة التغير السنوية للمؤشلر الرئيسى للبورصه المصرية EGX30 | U1: الانحراف المعياري للمؤشر الرئيسى للبورصة المصرية EGX30 | V1: نسبه التغير المؤشر الرئيسى للبورصه | W1: دولار | X1: فضة | Y1: ذهب | Z1: بورصة
A7: التاريخ | B7: السنه | C7: سعر اليورو | D7: نسبة التغير السنوية لليورو | E7: الانحراف المعياري لليورو | F7: نسبه التغير لليورو التراكميه خلال 20 سنة | G7: سعر الدولار | H7: نسبة التغير السنوية الدولار | I7: الانحراف المعياري للدولار | J7: متوسط نسبه التغير للدولار التراكمية | K7: سعر الفضة | L7: نسبة التغير السنوية للفضه | M7: الانحراف المعياري للفضه | N7: نسبه التغير الفضه التراكميه | O7: سعر الذهب | P7: نسبة التغير السنوية للذهب | Q7: الانحراف المعياري للذهب | R7: نسبه التغير الذهب | S7: مؤشر البورصه المصرية | T7: نسبة التغير السنوية للمؤشر الرئيسى للبورصه المصرية EGX30 | U7: الانحراف المعياري للمؤشر الرئيسى للبورصة المصرية EGX30 | V7: نسبه التغير المؤشر الرئيسى للبورصه
A8: 45992 | B8: 2025 | C8: 55.3642 | D8: =(C8-C9)/C9 -> 0.05400008 | E8: =_xlfn.STDEV.P(D8:D27) -> 0.32803842 | F8: =AVERAGE('data set 1 '!E2:E13) -> 6.67192 | G8: 47.6006 | H8: =(G8-G9)/G9 -> -0.041421739 | I8: =_xlfn.STDEV.P(H8:H27) -> 0.32900676 | J8: =AVERAGE('data set 1 '!G2:G13) -> 8.0836252 | K8: 70.363 | L8: =(K8-K9)/K9 -> 1.3923229 | M8: =_xlfn.STDEV.P(L8:L27) -> 0.39869625 | N8: =AVERAGE('data set 1 '!I2:I13) -> 6.1727916 | O8: 4357.1 | P8: =(O8-O9)/O9 -> 0.66422215 | Q8: =_xlfn.STDEV.P(P8:P27) -> 0.19053951 | R8: =AVERAGE('data set 1 '!K2:K13) -> 8.2962352 | S8: 42624.11 | T8: =(S8-S9)/S9 -> 0.36472572 | U8: =_xlfn.STDEV.P(T8:T27) -> 0.33841884 | V8: =AVERAGE('data set 1 '!M2:M13) -> 9.9346834
A9: 45627 | B9: 2024 | C9: 52.5277 | D9: =(C9-C10)/C10 -> 0.55875947 | F9: =AVERAGE('data set 1 '!E14:E25) -> 5.7329112 | G9: 49.6575 | H9: =(G9-G10)/G10 -> 0.60399695 | J9: =AVERAGE('data set 1 '!G14:G25) -> 7.2039183 | K9: 29.412 | L9: =(K9-K10)/K10 -> 0.20679468 | N9: =AVERAGE('data set 1 '!I14:I25) -> 4.2124371 | O9: 2618.1 | P9: =(O9-O10)/O10 -> 0.25658747 | R9: =AVERAGE('data set 1 '!K14:K25) -> 5.6886151 | S9: 31232.73 | T9: =(S9-S10)/S10 -> 0.21147719 | V9: =AVERAGE('data set 1 '!M14:M25) -> 8.6704552
A10: 45261 | B10: 2023 | C10: 33.6984 | D10: =(C10-C11)/C11 -> 0.31040597 | F10: =AVERAGE('data set 1 '!E26:E37) -> 3.9401532 | G10: 30.9586 | H10: =(G10-G11)/G11 -> 0.25707441 | J10: =AVERAGE('data set 1 '!G26:G37) -> 4.9686929 | K10: 24.372 | L10: =(K10-K11)/K11 -> 0.0050309278 | N10: =AVERAGE('data set 1 '!I26:I37) -> 3.5282091 | O10: 2083.5 | P10: =(O10-O11)/O11 -> 0.14101862 | R10: =AVERAGE('data set 1 '!K26:K37) -> 4.6320247 | S10: 25780.7 | T10: =(S10-S11)/S11 -> 0.65306887 | V10: =AVERAGE('data set 1 '!M26:M37) -> 5.6366237
A11: 44896 | B11: 2022 | C11: 25.716 | D11: =(C11-C12)/C12 -> 0.43939012 | F11: =AVERAGE('data set 1 '!E38:E49) -> 2.4118744 | G11: 24.6275 | H11: =(G11-G12)/G12 -> 0.56097484 | J11: =AVERAGE('data set 1 '!G38:G49) -> 3.1164133 | K11: 24.25 | L11: =(K11-K12)/K12 -> 0.05160451 | N11: =AVERAGE('data set 1 '!I38:I49) -> 3.1900449 | O11: 1826 | P11: =(O11-O12)/O12 -> -0.0014218528 | R11: =AVERAGE('data set 1 '!K38:K49) -> 4.2338285 | S11: 15595.66 | T11: =(S11-S12)/S12 -> 0.30503902 | V11: =AVERAGE('data set 1 '!M38:M49) -> 3.2829077
A12: 44531 | B12: 2021 | C12: 17.8659 | D12: =(C12-C13)/C13 -> -0.05076668 | F12: =AVERAGE('data set 1 '!E50:E61) -> 2.2490249 | G12: 15.777 | H12: =(G12-G13)/G13 -> 0.0032111404 | J12: =AVERAGE('data set 1 '!G50:G61) -> 2.5807832 | K12: 23.06 | L12: =(K12-K13)/K13 -> -0.13220186 | N12: =AVERAGE('data set 1 '!I50:I61) -> 3.7002243 | O12: 1828.6 | P12: =(O12-O13)/O13 -> -0.035090497 | R12: =AVERAGE('data set 1 '!K50:K61) -> 4.2286803 | S12: 11950.34 | T12: =(S12-S13)/S13 -> 0.076246519 | V12: =AVERAGE('data set 1 '!M50:M61) -> 3.1887989
A13: 44166 | B13: 2020 | C13: 18.8214 | D13: =(C13-C14)/C14 -> 0.05549636 | F13: =AVERAGE('data set 1 '!E62:E73) -> 2.1780862 | G13: 15.7265 | H13: =(G13-G14)/G14 -> -0.028190599 | J13: =AVERAGE('data set 1 '!G62:G73) -> 2.60125 | K13: 26.573 | L13: =(K13-K14)/K14 -> 0.47619577 | N13: =AVERAGE('data set 1 '!I62:I73) -> 3.0760623 | O13: 1895.1 | P13: =(O13-O14)/O14 -> 0.24423872 | R13: =AVERAGE('data set 1 '!K62:K73) -> 4.2006602 | S13: 11103.72 | T13: =(S13-S14)/S14 -> -0.21208135 | V13: =AVERAGE('data set 1 '!M62:M73) -> 3.324972
A14: 43800 | B14: 2019 | C14: 17.8318 | D14: =(C14-C15)/C15 -> -0.12350758 | F14: =AVERAGE('data set 1 '!E74:E85) -> 2.282508 | G14: 16.1827 | H14: =(G14-G15)/G15 -> -0.099650603 | J14: =AVERAGE('data set 1 '!G74:G85) -> 2.7738843 | K14: 18.001 | L14: =(K14-K15)/K15 -> 0.17961992 | N14: =AVERAGE('data set 1 '!I74:I85) -> 2.4207705 | O14: 1523.1 | P14: =(O14-O15)/O15 -> 0.18713952 | R14: =AVERAGE('data set 1 '!K74:K85) -> 3.318164 | S14: 14092.47 | T14: =(S14-S15)/S15 -> 0.059176467 | V14: =AVERAGE('data set 1 '!M74:M85) -> 4.1646091
A15: 43435 | B15: 2018 | C15: 20.3445 | D15: =(C15-C16)/C16 -> -0.037110836 | F15: =AVERAGE('data set 1 '!E86:E97) -> 2.5401584 | G15: 17.9738 | H15: =(G15-G16)/G16 -> 0.011719278 | J15: =AVERAGE('data set 1 '!G86:G97) -> 2.9232194 | K15: 15.26 | L15: =(K15-K16)/K16 -> -0.098268628 | N15: =AVERAGE('data set 1 '!I86:I97) -> 2.3083777 | O15: 1283 | P15: =(O15-O16)/O16 -> -0.020087069 | R15: =AVERAGE('data set 1 '!K86:K97) -> 2.99047 | S15: 13305.12 | T15: =(S15-S16)/S16 -> -0.11653176 | V15: =AVERAGE('data set 1 '!M86:M97) -> 4.5330158
A16: 43070 | B16: 2017 | C16: 21.1286 | D16: =(C16-C17)/C17 -> 0.097891887 | F16: =AVERAGE('data set 1 '!E98:E109) -> 2.4239123 | G16: 17.7656 | H16: =(G16-G17)/G17 -> -0.019163349 | J16: =AVERAGE('data set 1 '!G98:G109) -> 2.9300517 | K16: 16.923 | L16: =(K16-K17)/K17 -> 0.05841516 | N16: =AVERAGE('data set 1 '!I98:I109) -> 2.5530045 | O16: 1309.3 | P16: =(O16-O17)/O17 -> 0.13684119 | R16: =AVERAGE('data set 1 '!K98:K109) -> 2.9986442 | S16: 15060.1 | T16: =(S16-S17)/S17 -> 0.20153981 | V16: =AVERAGE('data set 1 '!M98:M109) -> 3.9156653
A17: 42705 | B17: 2016 | C17: 19.2447 | D17: =(C17-C18)/C18 -> 1.3460563 | F17: =AVERAGE('data set 1 '!E110:E121) -> 1.2373969 | G17: 18.1127 | H17: =(G17-G18)/G18 -> 1.3401119 | J17: =AVERAGE('data set 1 '!G110:G121) -> 1.5226433 | K17: 15.989 | L17: =(K17-K18)/K18 -> 0.15837137 | N17: =AVERAGE('data set 1 '!I110:I121) -> 2.5347037 | O17: 1151.7 | P17: =(O17-O18)/O18 -> 0.086304471 | R17: =AVERAGE('data set 1 '!K110:K121) -> 2.9473591 | S17: 12534 | T17: =(S17-S18)/S18 -> 0.78291001 | V17: =AVERAGE('data set 1 '!M110:M121) -> 2.408432
A18: 42339 | B18: 2015 | C18: 8.203 | D18: =(C18-C19)/C19 -> -0.08483388 | F18: =AVERAGE('data set 1 '!E122:E133) -> 1.0180148 | G18: 7.7401 | H18: =(G18-G19)/G19 -> 0.082516328 | J18: =AVERAGE('data set 1 '!G122:G133) -> 1.2503505 | K18: 13.803 | L18: =(K18-K19)/K19 -> -0.11513559 | N18: =AVERAGE('data set 1 '!I122:I133) -> 2.2944765 | O18: 1060.2 | P18: =(O18-O19)/O19 -> -0.10463643 | R18: =AVERAGE('data set 1 '!K122:K133) -> 2.7173623 | S18: 7030.08 | T18: =(S18-S19)/S19 -> -0.26608462 | V18: =AVERAGE('data set 1 '!M122:M133) -> 2.4358685
A19: 41974 | B19: 2014 | C19: 8.9634 | D19: =(C19-C20)/C20 -> -0.042515008 | F19: =AVERAGE('data set 1 '!E134:E145) -> 1.1353342 | G19: 7.1501 | H19: =(G19-G20)/G20 -> 0.038142115 | J19: =AVERAGE('data set 1 '!G134:G145) -> 1.1578911 | K19: 15.599 | L19: =(K19-K20)/K20 -> -0.1946825 | N19: =AVERAGE('data set 1 '!I134:I145) -> 2.7517623 | O19: 1184.1 | P19: =(O19-O20)/O20 -> -0.015137653 | R19: =AVERAGE('data set 1 '!K134:K145) -> 2.9517606 | S19: 9578.87 | T19: =(S19-S20)/S20 -> 0.39303488 | V19: =AVERAGE('data set 1 '!M134:M145) -> 2.526538
A20: 41609 | B20: 2013 | C20: 9.3614 | D20: =(C20-C21)/C21 -> 0.17774199 | F20: =AVERAGE('data set 1 '!E146:E157) -> 1.1006646 | G20: 6.8874 | H20: =(G20-G21)/G21 -> 0.12522668 | J20: =AVERAGE('data set 1 '!G146:G157) -> 1.1282491 | K20: 19.37 | L20: =(K20-K21)/K21 -> -0.35918219 | N20: =AVERAGE('data set 1 '!I146:I157) -> 3.4531081 | O20: 1202.3 | P20: =(O20-O21)/O21 -> -0.28255162 | R20: =AVERAGE('data set 1 '!K146:K157) -> 3.2887487 | S20: 6876.26 | T20: =(S20-S21)/S21 -> 0.2490459 | V20: =AVERAGE('data set 1 '!M146:M157) -> 1.6458752
A21: 41244 | B21: 2012 | C21: 7.9486 | D21: =(C21-C22)/C22 -> -0.020118839 | F21: =AVERAGE('data set 1 '!E158:E169) -> 0.94117541 | G21: 6.1209 | H21: =(G21-G22)/G22 -> 0.017605985 | J21: =AVERAGE('data set 1 '!G158:G169) -> 0.99394777 | K21: 30.227 | L21: =(K21-K22)/K22 -> 0.082822855 | N21: =AVERAGE('data set 1 '!I158:I169) -> 4.641329 | O21: 1675.8 | P21: =(O21-O22)/O22 -> 0.069568547 | R21: =AVERAGE('data set 1 '!K158:K169) -> 3.9573803 | S21: 5505.21 | T21: =(S21-S22)/S22 -> 0.33825589 | V21: =AVERAGE('data set 1 '!M158:M169) -> 1.5010068
A22: 40878 | B22: 2011 | C22: 8.1118 | D22: =(C22-C23)/C23 -> 0.067861985 | F22: =AVERAGE('data set 1 '!E170:E181) -> 1.0018339 | G22: 6.015 | H22: =(G22-G23)/G23 -> 0.037534067 | J22: =AVERAGE('data set 1 '!G170:G181) -> 0.97358595 | K22: 27.915 | L22: =(K22-K23)/K23 -> -0.097682387 | N22: =AVERAGE('data set 1 '!I170:I181) -> 5.2823745 | O22: 1566.8 | P22: =(O22-O23)/O23 -> 0.10229351 | R22: =AVERAGE('data set 1 '!K170:K181) -> 3.7152794 | S22: 4113.72 | T22: =(S22-S23)/S23 -> -0.42455555 | V22: =AVERAGE('data set 1 '!M170:M181) -> 1.518913
A23: 40513 | B23: 2010 | C23: 7.5963 | D23: =(C23-C24)/C24 -> -0.081263153 | F23: =AVERAGE('data set 1 '!E182:E193) -> 0.90306941 | G23: 5.7974 | H23: =(G23-G24)/G24 -> 0.056666363 | J23: =AVERAGE('data set 1 '!G182:G193) -> 0.92236841 | K23: 30.937 | L23: =(K23-K24)/K24 -> 0.83656871 | N23: =AVERAGE('data set 1 '!I182:I193) -> 3.0689638 | O23: 1421.4 | P23: =(O23-O24)/O24 -> 0.29666119 | R23: =AVERAGE('data set 1 '!K182:K193) -> 2.9214218 | S23: 7148.77 | T23: =(S23-S24)/S24 -> 0.065689046 | V23: =AVERAGE('data set 1 '!M182:M193) -> 1.9629774
A24: 40148 | B24: 2009 | C24: 8.2682 | D24: =(C24-C25)/C25 -> 0.18274279 | F24: =AVERAGE('data set 1 '!E194:E205) -> 0.93265207 | G24: 5.4865 | H24: =(G24-G25)/G25 -> -0.0073456243 | J24: =AVERAGE('data set 1 '!G194:G205) -> 0.91098538 | K24: 16.845 | L24: =(K24-K25)/K25 -> 0.49136786 | N24: =AVERAGE('data set 1 '!I194:I205) -> 2.1861136 | O24: 1096.2 | P24: =(O24-O25)/O25 -> 0.23962456 | R24: =AVERAGE('data set 1 '!K194:K205) -> 2.3249823 | S24: 6708.12 | T24: =(S24-S25)/S25 -> 0.45143367 | V24: =AVERAGE('data set 1 '!M194:M205) -> 1.684381
A25: 39783 | B25: 2008 | C25: 6.9907 | D25: =(C25-C26)/C26 -> -0.13799354 | F25: =AVERAGE('data set 1 '!E206:E217) -> 0.96247525 | G25: 5.5271 | H25: =(G25-G26)/G26 -> -0.0024365592 | J25: =AVERAGE('data set 1 '!G206:G217) -> 0.89194637 | K25: 11.295 | L25: =(K25-K26)/K26 -> -0.24296247 | N25: =AVERAGE('data set 1 '!I206:I217) -> 2.2225919 | O25: 884.3 | P25: =(O25-O26)/O26 -> 0.055250597 | R25: =AVERAGE('data set 1 '!K206:K217) -> 2.0768687 | S25: 4621.72 | T25: =(S25-S26)/S26 -> -0.56191148 | V25: =AVERAGE('data set 1 '!M206:M217) -> 2.6924221
A26: 39417 | B26: 2007 | C26: 8.1098 | D26: =(C26-C27)/C27 -> 0.061672798 | F26: =AVERAGE('data set 1 '!E218:E229) -> 0.92998332 | G26: 5.5406 | H26: =(G26-G27)/G27 -> -0.032327925 | J26: =AVERAGE('data set 1 '!G218:G229) -> 0.92596593 | K26: 14.92 | L26: =(K26-K27)/K27 -> 0.15345961 | N26: =AVERAGE('data set 1 '!I218:I229) -> 2.0165139 | O26: 838 | P26: =(O26-O27)/O27 -> 0.31347962 | R26: =AVERAGE('data set 1 '!K218:K229) -> 1.676904 | S26: 10549.74 | T26: =(S26-S27)/S27 -> 0.51265933 | V26: =AVERAGE('data set 1 '!M218:M229) -> 2.3755024
A27: 39052 | B27: 2006 | C27: 7.6387 | D27: =(C27-C28)/C28 -> 0.12476073 | F27: =AVERAGE('data set 1 '!E230:E241) -> 0.86646563 | G27: 5.7257 | H27: =(G27-G28)/G28 -> -0.0074368131 | J27: =AVERAGE('data set 1 '!G230:G241) -> 0.94105013 | K27: 12.935 | L27: =(K27-K28)/K28 -> 0.45500562 | N27: =AVERAGE('data set 1 '!I230:I241) -> 1.7693976 | O27: 638 | P27: =(O27-O28)/O28 -> 0.22763133 | R27: =AVERAGE('data set 1 '!K230:K241) -> 1.4596597 | S27: 6974.3 | T27: =(S27-S28)/S28 -> 0.10178341 | V27: =AVERAGE('data set 1 '!M230:M241) -> 1.9259175
A28: 38687 | B28: 2005 | C28: 6.7914 | F28: =AVERAGE('data set 1 '!E242:E253) -> 0.87749737 | G28: 5.7686 | J28: =AVERAGE('data set 1 '!G242:G253) -> 0.95218497 | K28: 8.89 | N28: =AVERAGE('data set 1 '!I242:I253) -> 1.100944 | O28: 519.7 | R28: =AVERAGE('data set 1 '!K242:K253) -> 1.064293 | S28: 6330.01 | V28: =AVERAGE('data set 1 '!M242:M253) -> 1.4017727
C30: 8.3154 | G30: 6.1107 | H30: 1 | J30: 1 | K30: 6.762 | O30: 424.1 | S30: 3538.51
F32: =C8/C30 -> 6.6580321 | G32: =G8/G30 -> 7.7897131 | H32: =K8/K30 -> 10.405649 | I32: =O8/O30 -> 10.273756 | J32: =S8/S30 -> 12.045779 | N32: =((S8/S28)^1/20)-1 -> -0.6633172 | O32: =J34 -> 0.13250922 | P32: معدل النمو السنوى المركب للبورصة | T32: Row Labels | U32: نسبة التغير السنوية لليورو
D33: 1.108976 | F33: =F32^(1/20) -> 1.0994293 | G33: =G32^(1/20) -> 1.1080926 | H33: =H32^(1/20) -> 1.1242515 | I33: =I32^(1/20) -> 1.1235346 | J33: =J32^(1/20) -> 1.1325092 | O33: =I34 -> 0.12353463 | P33: معدل النمو السنوى المركب للذهب | T33: 2005
D34: 0.10897595 | F34: =F33-1 -> 0.099429268 | G34: =G33-1 -> 0.10809265 | H34: =H33-1 -> 0.12425146 | I34: =I33-1 -> 0.12353463 | J34: =J33-1 -> 0.13250922 | O34: =H34 -> 0.12425146 | P34: معدل النمو السنوى المركب للفضة | T34: 2006 | U34: 0.12476073
O35: =G34 -> 0.10809265 | P35: معدل النمو السنوى المركب للدولار | T35: 2007 | U35: 0.061672798
O36: =F34 -> 0.099429268 | P36: معدل النمو السنوى المركب لليورو | T36: 2008 | U36: -0.13799354
T37: 2009 | U37: 0.18274279
T38: 2010 | U38: -0.081263153
T39: 2011 | U39: 0.067861985
T40: 2012 | U40: -0.020118839
T41: 2013 | U41: 0.17774199
T42: 2014 | U42: -0.042515008
T43: 2015 | U43: -0.08483388
T44: 2016 | U44: 1.3460563
T45: 2017 | U45: 0.097891887
T46: 2018 | U46: -0.037110836
T47: 2019 | U47: -0.12350758
...

Sheet DASHBOARD 1
AE4: احر تحديث بتاريخ 31-12-2025
Y35: مؤشر البورصه EGX30
